{"remainingRequest":"C:\\xampp\\htdocs\\GroupReads\\node_modules\\@angular-devkit\\build-optimizer\\src\\build-optimizer\\webpack-loader.js??ref--3-1!C:\\xampp\\htdocs\\GroupReads\\node_modules\\rxjs\\_esm5\\operators\\catchError.js","dependencies":[{"path":"C:\\xampp\\htdocs\\GroupReads\\node_modules\\rxjs\\_esm5\\operators\\catchError.js","mtime":1524743248361},{"path":"C:\\xampp\\htdocs\\GroupReads\\node_modules\\cache-loader\\dist\\cjs.js","mtime":1524743208736},{"path":"C:\\xampp\\htdocs\\GroupReads\\node_modules\\@angular-devkit\\build-optimizer\\src\\build-optimizer\\webpack-loader.js","mtime":1524743165754}],"contextDependencies":[],"result":["import { __extends } from \"tslib\";\r\nimport { OuterSubscriber } from '../OuterSubscriber';\r\nimport { subscribeToResult } from '../util/subscribeToResult';\r\n/**\r\n * Catches errors on the observable to be handled by returning a new observable or throwing an error.\r\n *\r\n * <img src=\"./img/catch.png\" width=\"100%\">\r\n *\r\n * @example <caption>Continues with a different Observable when there's an error</caption>\r\n *\r\n * Observable.of(1, 2, 3, 4, 5)\r\n *   .map(n => {\r\n * \t   if (n == 4) {\r\n * \t     throw 'four!';\r\n *     }\r\n *\t   return n;\r\n *   })\r\n *   .catch(err => Observable.of('I', 'II', 'III', 'IV', 'V'))\r\n *   .subscribe(x => console.log(x));\r\n *   // 1, 2, 3, I, II, III, IV, V\r\n *\r\n * @example <caption>Retries the caught source Observable again in case of error, similar to retry() operator</caption>\r\n *\r\n * Observable.of(1, 2, 3, 4, 5)\r\n *   .map(n => {\r\n * \t   if (n === 4) {\r\n * \t     throw 'four!';\r\n *     }\r\n * \t   return n;\r\n *   })\r\n *   .catch((err, caught) => caught)\r\n *   .take(30)\r\n *   .subscribe(x => console.log(x));\r\n *   // 1, 2, 3, 1, 2, 3, ...\r\n *\r\n * @example <caption>Throws a new error when the source Observable throws an error</caption>\r\n *\r\n * Observable.of(1, 2, 3, 4, 5)\r\n *   .map(n => {\r\n *     if (n == 4) {\r\n *       throw 'four!';\r\n *     }\r\n *     return n;\r\n *   })\r\n *   .catch(err => {\r\n *     throw 'error in source. Details: ' + err;\r\n *   })\r\n *   .subscribe(\r\n *     x => console.log(x),\r\n *     err => console.log(err)\r\n *   );\r\n *   // 1, 2, 3, error in source. Details: four!\r\n *\r\n * @param {function} selector a function that takes as arguments `err`, which is the error, and `caught`, which\r\n *  is the source observable, in case you'd like to \"retry\" that observable by returning it again. Whatever observable\r\n *  is returned by the `selector` will be used to continue the observable chain.\r\n * @return {Observable} An observable that originates from either the source or the observable returned by the\r\n *  catch `selector` function.\r\n * @name catchError\r\n */\r\nexport function catchError(selector) {\r\n    return function catchErrorOperatorFunction(source) {\r\n        var operator = new CatchOperator(selector);\r\n        var caught = source.lift(operator);\r\n        return (operator.caught = caught);\r\n    };\r\n}\r\nvar CatchOperator = /*@__PURE__*/ (function () {\r\n    function CatchOperator(selector) {\r\n        this.selector = selector;\r\n    }\r\n    CatchOperator.prototype.call = function (subscriber, source) {\r\n        return source.subscribe(new CatchSubscriber(subscriber, this.selector, this.caught));\r\n    };\r\n    return CatchOperator;\r\n}());\r\n/**\r\n * We need this JSDoc comment for affecting ESDoc.\r\n * @ignore\r\n * @extends {Ignored}\r\n */\r\nvar CatchSubscriber = /*@__PURE__*/ (function (_super) {\r\n    __extends(CatchSubscriber, _super);\r\n    function CatchSubscriber(destination, selector, caught) {\r\n        _super.call(this, destination);\r\n        this.selector = selector;\r\n        this.caught = caught;\r\n    }\r\n    // NOTE: overriding `error` instead of `_error` because we don't want\r\n    // to have this flag this subscriber as `isStopped`. We can mimic the\r\n    // behavior of the RetrySubscriber (from the `retry` operator), where\r\n    // we unsubscribe from our source chain, reset our Subscriber flags,\r\n    // then subscribe to the selector result.\r\n    CatchSubscriber.prototype.error = function (err) {\r\n        if (!this.isStopped) {\r\n            var result = void 0;\r\n            try {\r\n                result = this.selector(err, this.caught);\r\n            }\r\n            catch (err2) {\r\n                _super.prototype.error.call(this, err2);\r\n                return;\r\n            }\r\n            this._unsubscribeAndRecycle();\r\n            this.add(subscribeToResult(this, result));\r\n        }\r\n    };\r\n    return CatchSubscriber;\r\n}(OuterSubscriber));\r\n//# sourceMappingURL=catchError.js.map\r\n",null]}